Workbook
Name Anrede: #REF!
Name ApartmentUsage: #REF!
Name BasementHeatingLevel: DropDownData!$AF$4:$AF$6
Name BestKnownWeatherStations: DropDownData!$L$4:$L$43
Name Boolean: DropDownData!$BO$4:$BO$5
Name BuildingUsageSubTypes: DropDownData!$R$4
Name BuildingUsageTypes: DropDownData!$N$4:$N$11
Name BuildingUsageTypeSelection: Gebäudenutzungen!$B$5:$D$5
Name BüroVerwaltung: DropDownData!$D$4:$D$7
Name CalculationBase_NoMeter: DropDownData!$X$4:$X$5
Name CalculationBase_OnlyLump: DropDownData!$AO$4
Name Condition: #REF!
Name ConstructionType: DropDownData!$I$4:$I$7
Name ConsumerMeterType: DropDownData!$CC$4:$CC$5
Name Country: #REF!
Name DeviceQualities: #REF!
Name DeviceQuality: DropDownData!$BN$4:$BN$7
Name Devices: DropDownData!$BL$4:$BL$24
Name DeviceType: #REF!
Name DirectNeighborsCount: #REF!
Name Einfamilienhaus: DropDownData!$B$4:$B$8
Name ElectricityProducerType: DropDownData!$BY$4:$BY$5
Name ElectronicsQualities: DropDownData!$BS$4:$BS$7
Name EMS_ExpertCode: DropDownData!$CA$4
Name EnergyManagementSystemType: DropDownData!$CB$4:$CB$6
Name EnergySource: #REF!
Name EnergySources: DropDownData!$AQ$4:$AQ$19
Name ExpansionDegrees: DropDownData!$BQ$4:$BQ$6
Name ExpertCodes: DropDownData!$BE$4:$BE$9
Name FacadeStructure: DropDownData!$S$4:$S$6
Name FanType: DropDownData!$AN$4:$AN$6
Name FloorHeating: #REF!
Name FloorType: DropDownData!$AH$4:$AH$11
Name Flow: #REF!
Name GeneralCondition: DropDownData!$T$4:$T$7
Name GroundPlan: #REF!
Name GroundPlanType: DropDownData!$J$4:$J$5
Name HeatEmission: DropDownData!$BD$4:$BD$6
Name HeaterExpertCodes: 'Versorgter Bereich Heizung'!$A$10:$A$14
Name HeatExchangerType: DropDownData!$AM$4:$AM$7
Name HeatingFlows: DropDownData!$BG$4:$BG$11
Name HeatingScope: #REF!
Name HeatingSupplyType: DropDownData!$AU$4:$AU$6
Name HeatingType: DropDownData!$BC$4:$BC$5
Name HeatProducerCondition: DropDownData!$AV$4:$AV$6
Name HeatProducerExpertCodes: Speicher!$A$4:$A$8
Name HeatProducerExpertCodes: Wärmeerzeuger!$A$4:$A$8
Name HeatProducerOversize: DropDownData!$AR$4:$AR$8
Name HeatProducerTypes: DropDownData!$AS$4:$AS$31
Name HeatReservoir: #REF!
Name HeatUnit: DropDownData!$BK$4:$BK$11
Name HeizungsspeichervolumeninLiter: DropDownData!$AZ$4:$AZ$5
Name Hotel: DropDownData!$C$4:$C$10
Name HotelType: DropDownData!$O$4:$O$10
Name HpExpertCodes: DropDownData!$AP$4:$AP$8
Name HydraulicBalance: #REF!
Name InOutBuilding: #REF!
Name InOutThermalEnvelope: DropDownData!$AW$4:$AW$5
Name Land: #REF!
Name Land: #REF!

Sheet Projekt
A1: Projekt
A2: Projektbezeichnung | B2: Testobjekt EFH Meier | D2: Template R6.8 generiert am: | E2: 2025-11-30T09:37:26.73425357323139775
A4: Auftraggeber | D4: EGID_EDID-Gruppe
A5: Anrede | B5: Frau | D5: EGID | E5: EDID | F5: Adresse | G5: PLZ/Ort
A6: Name 1 | B6: Helene Meier
A7: Name 2 | B7: Jaggeler
A8: Adresse | B8: Sonnenweg 34
A9: Postfach | B9: 23
A10: PLZ | B10: 6414
A11: Ort | B11: Oberarth
A12: Land | B12: Schweiz
A13: E-Mail | B13: helene.meier@testmail.ch
A14: Telefon 1 | B14: 41416443434
A15: Telefon 2 | B15: 41792323233
A17: Gebäude
A18: PLZ | B18: 6487
A19: Ort | B19: Göschenen
A20: Gemeinde
A21: Strasse | B21: Breite
A22: Hausnummer | B22: 4
A23: Gebäudebezeichnung | B23: Provisorium
A24: Baujahr | B24: 1950
A25: Jahr der letzten Gesamtsanierung | B25: 1999
A26: Parzellen-Nummer | B26: 23-123
A27: Klimastation | B27: Altdorf
A28: Bestbekannte Werte Klimastation | B28: Altdorf
A29: Höhe ü. M. | B29: 1100
A30: Energiebezugsfläche [m²] | B30: 0
A31: Lichte Raumhöhe [m] | B31: 2.4
A32: Anzahl der Vollgeschosse | B32: 3
A33: Gebäudebreite [m] | B33: 22
A34: Bauweise Gebäude | B34: leicht
A35: Grundrisstyp | B35: kompakt
A37: Beschreibungen im Ist-Zustand
A38: Beschreibung des Gebäudes | B38: Einfache Holzkontruktion
A40: Gebäudehülle
A41: Beschreibung der Gebäudehülle | B41: Holzrahmen mit Steinwolle isoliert. Eternit Fassade
A43: Gebäudetechnik
A44: Beschreibung Gebäudetechnik | B44: Ölheizung

Sheet Gebäudenutzungen
A1: Gebäudenutzungen
B4: Nutzung 1 | C4: Nutzung 2 | D4: Nutzung 3
A5: Nutzungsart
A6: Nutzungsart II | E6: Gesamt
A7: Fläche [m²] | E7: =SUM(B7:D7) -> 0
A8: Fläche [%] | B8: =IF(ISBLANK(B7),"",B7/$E$7) | C8: =IF(ISBLANK(C7),"",C7/$E$7) | D8: =IF(ISBLANK(D7),"",D7/$E$7) | E8: =IF(OR(ISBLANK(E7),E7=0),"",E7/$E$7)
A9: Baujahr
A11: Standard-Nutzungsdaten überschreiben
A12: Raumtemperatur [°C]
A13: Regelungszuschlag für Raumtemperatur [K]
A14: Personenfläche [m²/P]
A15: Wärmeabgabe pro Person [W/P]
A16: Präsenzzeit pro Tag [h/d]
A17: Elektrizitätsbedarf pro Jahr [MJ/m²]
A18: Reduktionsfaktor Elektrizität
A19: Energiebedarf Warmwasser [kWh/m²]
A21: Nutzung 1 | C21: Nutzung 2 | E21: Nutzung 3
A22: =IF(B5="Restaurant","Anzahl Sitze",IF(B5="Hotel","Belegung «Ganzes Jahr»? (1=Ja, 0=Nein)",IF(B5="Schule","Anzahl Schüler",IF(B5="Büro/Verwaltung","Anzahl Personal",IF(B5="Einfamilienhaus","Anzahl Personen",IF(B5="Mehrfamilienhaus","Anzahl Personen","")))))) | C22: =IF(C5="Restaurant","Anzahl Sitze",IF(C5="Hotel","Belegung «Ganzes Jahr»? (1=Ja, 0=Nein)",IF(C5="Schule","Anzahl Schüler",IF(C5="Büro/Verwaltung","Anzahl Personal",IF(C5="Einfamilienhaus","Anzahl Personen",IF(C5="Mehrfamilienhaus","Anzahl Personen","")))))) | E22: =IF(D5="Restaurant","Anzahl Sitze",IF(D5="Hotel","Belegung «Ganzes Jahr»? (1=Ja, 0=Nein)",IF(D5="Schule","Anzahl Schüler",IF(D5="Büro/Verwaltung","Anzahl Personal",IF(D5="Einfamilienhaus","Anzahl Personen",IF(D5="Mehrfamilienhaus","Anzahl Personen",""))))))
A23: =IF(B5="Hotel","Anzahl Übernachtungen",IF(B5="Schule","Anzahl Klassenzimmer",IF(B5="Büro/Verwaltung","Anzahl Arbeitsplätze",IF(B5="Einfamilienhaus","Anzahl 1-Zimmer-Wohnungen",IF(B5="Mehrfamilienhaus","Anzahl 1-Zimmer-Wohnungen",""))))) | C23: =IF(C5="Hotel","Anzahl Übernachtungen",IF(C5="Schule","Anzahl Klassenzimmer",IF(C5="Büro/Verwaltung","Anzahl Arbeitsplätze",IF(C5="Einfamilienhaus","Anzahl 1-Zimmer-Wohnungen",IF(C5="Mehrfamilienhaus","Anzahl 1-Zimmer-Wohnungen",""))))) | E23: =IF(D5="Hotel","Anzahl Übernachtungen",IF(D5="Schule","Anzahl Klassenzimmer",IF(D5="Büro/Verwaltung","Anzahl Arbeitsplätze",IF(D5="Einfamilienhaus","Anzahl 1-Zimmer-Wohnungen",IF(D5="Mehrfamilienhaus","Anzahl 1-Zimmer-Wohnungen","")))))
A24: =IF(B5="Hotel","Anzahl Zimmer",IF(B5="Schule","Turnhalle",IF(B5="Büro/Verwaltung","Mittlere Benutzungszeit der Arbeitsplätze (wegen Teilzeitarbeit oder Aussendienst), in %",IF(B5="Einfamilienhaus","Anzahl 2-Zimmer-Wohnungen",IF(B5="Mehrfamilienhaus","Anzahl 2-Zimmer-Wohnungen",""))))) | C24: =IF(C5="Hotel","Anzahl Zimmer",IF(C5="Schule","Turnhalle",IF(C5="Büro/Verwaltung","Mittlere Benutzungszeit der Arbeitsplätze (wegen Teilzeitarbeit oder Aussendienst), in %",IF(C5="Einfamilienhaus","Anzahl 2-Zimmer-Wohnungen",IF(C5="Mehrfamilienhaus","Anzahl 2-Zimmer-Wohnungen",""))))) | E24: =IF(D5="Hotel","Anzahl Zimmer",IF(D5="Schule","Turnhalle",IF(D5="Büro/Verwaltung","Mittlere Benutzungszeit der Arbeitsplätze (wegen Teilzeitarbeit oder Aussendienst), in %",IF(D5="Einfamilienhaus","Anzahl 2-Zimmer-Wohnungen",IF(D5="Mehrfamilienhaus","Anzahl 2-Zimmer-Wohnungen","")))))
A25: =IF(B5="Hotel","Anzahl Betten",IF(B5="Einfamilienhaus","Anzahl 3-Zimmer-Wohnungen",IF(B5="Mehrfamilienhaus","Anzahl 3-Zimmer-Wohnungen",""))) | C25: =IF(C5="Hotel","Anzahl Betten",IF(C5="Einfamilienhaus","Anzahl 3-Zimmer-Wohnungen",IF(C5="Mehrfamilienhaus","Anzahl 3-Zimmer-Wohnungen",""))) | E25: =IF(D5="Hotel","Anzahl Betten",IF(D5="Einfamilienhaus","Anzahl 3-Zimmer-Wohnungen",IF(D5="Mehrfamilienhaus","Anzahl 3-Zimmer-Wohnungen","")))
A26: =IF(B5="Hotel","Wellnessbereich vorhanden? (1=Ja, 0=Nein)",IF(B5="Einfamilienhaus","Anzahl 4-Zimmer-Wohnungen",IF(B5="Mehrfamilienhaus","Anzahl 4-Zimmer-Wohnungen",""))) | C26: =IF(C5="Hotel","Wellnessbereich vorhanden? (1=Ja, 0=Nein)",IF(C5="Einfamilienhaus","Anzahl 4-Zimmer-Wohnungen",IF(C5="Mehrfamilienhaus","Anzahl 4-Zimmer-Wohnungen",""))) | E26: =IF(D5="Hotel","Wellnessbereich vorhanden? (1=Ja, 0=Nein)",IF(D5="Einfamilienhaus","Anzahl 4-Zimmer-Wohnungen",IF(D5="Mehrfamilienhaus","Anzahl 4-Zimmer-Wohnungen","")))
A27: =IF(B5="Hotel","Schwimmhalle vorhanden? (1=Ja, 0=Nein)",IF(B5="Einfamilienhaus","Anzahl 5-Zimmer-Wohnungen",IF(B5="Mehrfamilienhaus","Anzahl 5-Zimmer-Wohnungen",""))) | C27: =IF(C5="Hotel","Schwimmhalle vorhanden? (1=Ja, 0=Nein)",IF(C5="Einfamilienhaus","Anzahl 5-Zimmer-Wohnungen",IF(C5="Mehrfamilienhaus","Anzahl 5-Zimmer-Wohnungen",""))) | E27: =IF(D5="Hotel","Schwimmhalle vorhanden? (1=Ja, 0=Nein)",IF(D5="Einfamilienhaus","Anzahl 5-Zimmer-Wohnungen",IF(D5="Mehrfamilienhaus","Anzahl 5-Zimmer-Wohnungen","")))
A28: =IF(B5="Hotel","Fitnessraum vorhanden? (1=Ja, 0=Nein)",IF(B5="Einfamilienhaus","Anzahl 6-Zimmer-Wohnungen",IF(B5="Mehrfamilienhaus","Anzahl 6-Zimmer-Wohnungen",""))) | C28: =IF(C5="Hotel","Fitnessraum vorhanden? (1=Ja, 0=Nein)",IF(C5="Einfamilienhaus","Anzahl 6-Zimmer-Wohnungen",IF(C5="Mehrfamilienhaus","Anzahl 6-Zimmer-Wohnungen",""))) | E28: =IF(D5="Hotel","Fitnessraum vorhanden? (1=Ja, 0=Nein)",IF(D5="Einfamilienhaus","Anzahl 6-Zimmer-Wohnungen",IF(D5="Mehrfamilienhaus","Anzahl 6-Zimmer-Wohnungen","")))
A29: =IF(B5="Hotel","Wäscherei vorhanden? (1=Ja, 0=Nein)",IF(B5="Einfamilienhaus","Anzahl Wohnungen mit über 6 Zimmer",IF(B5="Mehrfamilienhaus","Anzahl Wohnungen mit über 6 Zimmer",""))) | C29: =IF(C5="Hotel","Wäscherei vorhanden? (1=Ja, 0=Nein)",IF(C5="Einfamilienhaus","Anzahl Wohnungen mit über 6 Zimmer",IF(C5="Mehrfamilienhaus","Anzahl Wohnungen mit über 6 Zimmer",""))) | E29: =IF(D5="Hotel","Wäscherei vorhanden? (1=Ja, 0=Nein)",IF(D5="Einfamilienhaus","Anzahl Wohnungen mit über 6 Zimmer",IF(D5="Mehrfamilienhaus","Anzahl Wohnungen mit über 6 Zimmer","")))

Sheet Dächer und Decken
A1: Dächer und Decken
A3: Dachtyp
C4: Dächer / Decken gegen aussen | H4: Übrige Decken
A5: Allgemeiner Zustand
A6: Priorität
A7: Beschreibung
A8: Mögliche Verbesserungen
A10: Kürzel | B10: Bezeichnung | C10: Typ | D10: Ausrichtung | E10: Renovationsjahr | F10: Fläche [m²] | G10: U-Wert [W/(m²K)] | H10: b-Faktor [—] | I10: Anzahl [—] | J10: Bauteilheizung | K10: Temp. Nachbarraum | L10: Temperaturzuschlag Nachbarraum | M10: VL Nachbarzone | N10: Werterhalt | O10: Investition | P10: Berechnungsgrundlage | Q10: Nutzungsdauer [Jahre]

Sheet Wände
A1: Wände
A3: Fassadengliederung
C4: Wände gegen aussen | H4: Übrige Wände
A5: Allgemeiner Zustand
A6: Priorität
A7: Beschreibung
A8: Mögliche Verbesserungen
A10: Kürzel | B10: Bezeichnung | C10: Typ | D10: Ausrichtung | E10: Renovationsjahr | F10: Fläche [m²] | G10: U-Wert [W/(m²K)] | H10: b-Faktor [—] | I10: Anzahl [—] | J10: Bauteilheizung | K10: Temp. Nachbarraum | L10: Temperaturzuschlag Nachbarraum | M10: VL Nachbarzone | N10: Werterhalt | O10: Investition | P10: Berechnungsgrundlage | Q10: Nutzungsdauer [Jahre]

Sheet Fenster und Türen
A1: Fenster und Türen
A3: Allgemeiner Zustand
A4: Priorität
A5: Beschreibung
A6: Mögliche Verbesserungen
A7: Fensterflächen automatisch abziehen
A9: Kürzel | B9: Bezeichnung | C9: Typ | D9: Ausrichtung | E9: Renovationsjahr | F9: Fläche [m²] | G9: U-Wert [W/(m²K)] | H9: g-Wert [—] | I9: b-Faktor [—] | J9: Glasanteil [—] | K9: Verschattung [—] | L9: Anzahl [—] | M9: Eingebaut in | N9: Bauteilheizung | O9: Temp. Nachbarraum | P9: Temperaturzuschlag Nachbarraum | Q9: Werterhalt | R9: Investition | S9: Berechnungsgrundlage | T9: Nutzungsdauer [Jahre]

Sheet Böden
A1: Böden
A3: Teilbeheizungsgrad Kellergeschoss
C4: Böden gegen aussen | H4: Übrige Böden
A5: Allgemeiner Zustand
A6: Priorität
A7: Beschreibung
A8: Mögliche Verbesserungen
A10: Kürzel | B10: Bezeichnung | C10: Typ | D10: Renovationsjahr | E10: Fläche [m²] | F10: U-Wert [W/(m²K)] | G10: b-Faktor [—] | H10: Anzahl [—] | I10: Bauteilheizung | J10: Temp. Nachbarraum | K10: Temperaturzuschlag Nachbarraum | L10: VL Nachbarzone | M10: Werterhalt | N10: Investition | O10: Berechnungsgrundlage | P10: Nutzungsdauer [Jahre]

Sheet Wärmebrücken
A1: Wärmebrücken
A3: Priorität
A4: Beschreibung
A5: Mögliche Verbesserungen
A7: Kürzel | B7: Bezeichnung | C7: Typ | D7: Renovationsjahr | E7: Länge [m] | F7: Psi-Wert Ψ [W/(mK)] | G7: Chi-Wert Χ [W/K] | H7: Anzahl [—] | I7: b-Faktor [—]

Sheet Wärmeerzeuger
A1: Wärmeerzeuger (max. 5)
A3: Kürzel | B3: Bezeichnung | C3: Energieträger | D3: Nutzungsgrad Heizung | E3: Nutzungsgrad Warmwasser | F3: Überdimensionierung [—] | G3: Typ | H3: Versorgte Verteilsysteme | I3: Art der Wärmeabgabe | J3: Baujahr | K3: Zustand | L3: Aufstellort | M3: Instandhaltungskosten [CHF/a] | N3: Werterhalt | O3: Investition | P3: Berechnungsgrundlage | Q3: Nutzungsdauer [Jahre]

Sheet Speicher
A1: Speicher (max. 10)
A3: Kürzel | B3: Bezeichnung | C3: Typ | D3: Gesamtspeichervolumen in Liter | E3: Warmwasserspeichervolumen in Liter | F3: Heizungsspeichervolumen in Liter | G3: Aufstellort | H3: Ausführungsqualität Speicheranschlüsse | I3: Verhältnis der Speicherhöhe zum Speicherdurchmesser | J3: Instandhaltungskosten [CHF/a] | K3: WE-1 | L3: WE-2 | M3: WE-3 | N3: WE-4 | O3: WE-5 | P3: Werterhalt | Q3: Investition | R3: Berechnungsgrundlage | S3: Nutzungsdauer [Jahre]

Sheet Versorgter Bereich Heizung
A1: Versorgter Bereich Heizung (max. 3 Bereiche)
C3: Wärmeverteilung und -abgabe Heizung
A4: Allgemeiner Zustand
A5: Priorität
A6: Beschreibung
A7: Mögliche Verbesserungen
A9: Kürzel | B9: Bezeichnung | C9: Fläche [m²] | D9: Typ | E9: Art der Wärmeabgabe | F9: WE-1 Deckungsgrad [%] | G9: WE-2 Deckungsgrad [%] | H9: WE-3 Deckungsgrad [%] | I9: WE-4 Deckungsgrad [%] | J9: WE-5 Deckungsgrad [%] | K9: Hauptwärmeerzeuger | L9: Verteilleitungen gedämmt | M9: Dämmdicke [cm] | N9: Wärmeleitfähigkeit Dämmung [W/(mK)] | O9: Vorlauf/Rücklauf [°C] | P9: Lage der horizontalen Verteilleitungen | Q9: Hydraulischer Abgleich | R9: Werterhalt | S9: Investition | T9: Berechnungsgrundlage | U9: Nutzungsdauer [Jahre] | V9: Instandhaltungskosten [CHF/a]

Sheet Versorgter Bereich Warmwasser
A1: Versorgter Bereich Warmwasser (max. 3 Bereiche)
C3: Warmwasserverteilung und -amaturen
A4: Allgemeiner Zustand
A5: Priorität
A6: Beschreibung
A7: Mögliche Verbesserungen
A9: Kürzel | B9: Bezeichnung | C9: Fläche [m²] | D9: Typ | E9: WE-1 Deckungsgrad [%] | F9: WE-2 Deckungsgrad [%] | G9: WE-3 Deckungsgrad [%] | H9: WE-4 Deckungsgrad [%] | I9: WE-5 Deckungsgrad [%] | J9: Verteilleitungen gedämmt | K9: Dämmdicke [cm] | L9: Wärmeleitfähigkeit Dämmung [W/(mK)] | M9: Warmhaltung | N9: Lage der horizontalen Verteilleitungen | O9: Werterhalt | P9: Investition | Q9: Berechnungsgrundlage | R9: Nutzungsdauer [Jahre] | S9: Instandhaltungskosten [CHF/a]

Sheet Verbrauchsdaten HWW
A1: Durchschnittlicher Verbrauch pro Jahr
A3: Energieträger | B3: ∅ Jahresverbrauch | C3: Einheit | D3: Anteil Heizung [%] | E3: Anteil Warmwasser [%]

Sheet Geräte und Installationen
A1: Geräte und Installationen
A3: Allgemeiner Zustand
A4: Priorität
A5: Beschreibung
A6: Mögliche Verbesserungen
H8: Stromtarif-Anteile
A9: Kürzel | B9: Bezeichnung | C9: Nutzungsart | D9: Typ | E9: Qualität | F9: Verbrauch pro Jahr [kWh/a] | G9: Instandhaltungskosten [CHF/a] | H9: Hochtarif | I9: Mitteltarif | J9: Niedertarif | K9: Anzahl [—] | L9: Aktuelle Nutzungsdaten | M9: Werterhalt | N9: Investition | O9: Berechnungsgrundlage | P9: Nutzungsdauer [Jahre]

Sheet Kleingeräte und Elektronik
A1: Kleingeräte und Elektronik
H3: Stromtarif-Anteile
A4: Kürzel | B4: Bezeichnung | C4: Nutzungsart | D4: Typ | E4: Fläche [m²] | F4: Ausbaugrad | G4: Instandhaltungskosten [CHF/a] | H4: Hochtarif | I4: Mitteltarif | J4: Niedertarif | K4: Aktuelle Nutzungsdaten | L4: Werterhalt | M4: Investition | N4: Berechnungsgrundlage | O4: Nutzungsdauer [Jahre]

Sheet Beleuchtung
A1: Beleuchtung
I3: Stromtarif-Anteile
A4: Kürzel | B4: Bezeichnung | C4: Nutzungsart | D4: Typ | E4: Fläche [m²] | F4: Ausbaugrad | G4: Qualität | H4: Instandhaltungskosten [CHF/a] | I4: Hochtarif | J4: Mitteltarif | K4: Niedertarif | L4: Aktuelle Nutzungsdaten | M4: Werterhalt | N4: Investition | O4: Berechnungsgrundlage | P4: Nutzungsdauer [Jahre]

Sheet Betriebseinrichtungen und Gerät
A1: Betriebseinrichtungen und Geräte
A3: Allgemeiner Zustand
A4: Priorität
A5: Beschreibung
A6: Mögliche Verbesserungen
I8: Stromtarif-Anteile
A9: Kürzel | B9: Bezeichnung | C9: Nutzungsart | D9: Typ | E9: Fläche [m²] | F9: Ausbaugrad | G9: Qualität | H9: Instandhaltungskosten [CHF/a] | I9: Hochtarif | J9: Mitteltarif | K9: Niedertarif | L9: Werterhalt | M9: Investition | N9: Berechnungsgrundlage | O9: Nutzungsdauer [Jahre]

Sheet Elektrizitätsprod. ohne PVopti
A1: Elektrizitätsprod. ohne PVopti
A3: Allgemeiner Zustand
A4: Priorität
A5: Beschreibung
A6: Mögliche Verbesserungen
A8: Kürzel | B8: Typ | C8: Wärmeerzeuger | D8: Bezeichnung | E8: Inbetriebnahmejahr | F8: Stromproduktion (Jahresertrag) [kWh] | G8: Netzeinspeisung [%] | H8: Instandhaltungskosten [CHF/a] | I8: Eigenverbrauch mit einem externen Tool berechnet | J8: Werterhalt | K8: Investition | L8: Berechnungsgrundlage | M8: Nutzungsdauer [Jahre]

Sheet Elektrizitätsprod. mit PVopti
A1: Elektrizitätsprod. mit PVopti
A3: Allgemeiner Zustand
A4: Priorität
A5: Beschreibung
A6: Mögliche Verbesserungen
A8: Energiemanagement und Speicherbatterie (max. 1)
A10: Kürzel | B10: Energiemanagementsystem (EMS) | C10: Bezeichnung | D10: Speicherbatterie vorhanden? | E10: Elektrische Speicherkapazität | F10: Instandhaltungskosten [CHF/a] | G10: Werterhalt | H10: Investition | I10: Berechnungsgrundlage | J10: Nutzungsdauer [Jahre]
A16: Erzeugungsanlagen
A18: Kürzel | B18: Typ | C18: Wärmeerzeuger | D18: Bezeichnung | E18: Inbetriebnahmejahr | F18: Ausrichtung [°] | G18: Anstellwinkel [°] | H18: Installierte Leistung [kWp] | I18: Nutzungsgrad elektrisch | J18: Instandhaltungskosten [CHF/a] | K18: Werterhalt | L18: Investition | M18: Berechnungsgrundlage | N18: Nutzungsdauer [Jahre]

Sheet Weitere Verbraucher
A1: Weitere Verbraucher
G3: Stromtarif-Anteile
A4: Kürzel | B4: Bezeichnung | C4: Nutzungsart | D4: Leistung [kW] | E4: Jahreslaufzeit [h] | F4: Instandhaltungskosten [CHF/a] | G4: Hochtarif | H4: Mitteltarif | I4: Niedertarif | J4: Anzahl [—] | K4: Typ | L4: Werterhalt | M4: Investition | N4: Berechnungsgrundlage | O4: Nutzungsdauer [Jahre]

Sheet Verbrauchsdaten Elektrizität
A1: Verbrauchsdaten Elektrizität
E3: Stromtarif-Anteile
A4: Bezeichnung | B4: Nutzungsart | C4: Typ | D4: ∅ Jahresverbrauch [kWh/a] | E4: Hochtarif | F4: Mitteltarif | G4: Niedertarif | H4: ∅ Ertrag aus Photovoltaik und / oder Wärmekraftkopplung [kWh/a] | I4: Netzeinspeisung [kWh/a]

Sheet Lüftung
A1: Lüftung
A3: Priorität
A4: Beschreibung
A5: Mögliche Verbesserungen
E7: Stromtarif-Anteile | K7: Angaben bei Standard-Lüftungsanlagen
A8: Kürzel | B8: Bezeichnung | C8: Nutzungsart | D8: Standard-Lüftungsanlagentyp | E8: Hochtarif | F8: Mitteltarif | G8: Niedertarif | H8: Inbetriebnahmejahr | I8: Instandhaltungskosten [CHF/a] | J8: Anzahl [—] | K8: Anzahl Räume mit Zuluft/Anzahl Personen | L8: Wärmerückgewinnungs-Wärmetauscher | M8: Ventilatorantrieb mit | N8: Flächenbezogener Aussenluft-Volumenstrom [m³/(h m²)] | O8: Thermisch wirksame Aussenluftrate [m³/h] | P8: Strombedarf Lüftung + Vereisungsschutz [kWh] | Q8: Strombedarf Kälteförderung [kWh] | R8: Strombedarf Klima und Befeuchtung [kWh] | S8: Werterhalt | T8: Investition | U8: Berechnungsgrundlage | V8: Nutzungsdauer [Jahre]

Sheet DropDownData
A1: Language: | B1: de | C1: Version: | D1: 5
A3: Mehrfamilienhaus: | B3: Einfamilienhaus: | C3: Hotel: | D3: BüroVerwaltung: | E3: Schule: | F3: Verkauf: | G3: Restaurant: | H3: Title: | I3: ConstructionType: | J3: GroundPlanType: | K3: WeatherStations: | L3: BestKnownWeatherStations: | M3: Prioritization: | N3: BuildingUsageTypes: | O3: HotelType: | P3: RestaurantType: | Q3: ShopType: | R3: BuildingUsageSubTypes: | S3: FacadeStructure: | T3: GeneralCondition: | U3: WS3ExpertCodes: | V3: WallType: | W3: Orientation: | X3: CalculationBase_NoMeter: | Y3: RoofType: | Z3: WS2ExpertCodes: | AA3: RoofCeilingType: | AB3: OrientationHExtended: | AC3: WS4ExpertCodes: | AD3: WallOpeningType: | AE3: OrientationH: | AF3: BasementHeatingLevel: | AG3: WS5ExpertCodes: | AH3: FloorType: | AI3: WS6ExpertCodes: | AJ3: ThermalBridgeType: | AK3: WS20ExpertCodes: | AL3: StandardVentilationType: | AM3: HeatExchangerType: | AN3: FanType: | AO3: CalculationBase_OnlyLump: | AP3: HpExpertCodes: | AQ3: EnergySources: | AR3: HeatProducerOversize: | AS3: HeatProducerTypes: | AT3: SuppliedDistributionSystems: | AU3: HeatingSupplyType: | AV3: HeatProducerCondition: | AW3: InOutThermalEnvelope: | AX3: SpExpertCodes: | AY3: ReservoirType: | AZ3: Heizungsspeichervolumen in Liter: | BA3: Quality: | BB3: WS9ExpertCodes: | BC3: HeatingType: | BD3: HeatEmission: | BE3: ExpertCodes: | BF3: PartialBool: | BG3: HeatingFlows: | BH3: UnknownBool: | BI3: WS10ExpertCodes: | BJ3: WarmWaterWarmKeeping: | BK3: HeatUnit: | BL3: Devices: | BM3: WS12ExpertCodes: | BN3: DeviceQuality: | BO3: Boolean: | BP3: WS13ExpertCodes: | BQ3: ExpansionDegrees: | BR3: WS15ExpertCodes: | BS3: ElectronicsQualities: | BT3: WS14ExpertCodes: | BU3: LightingQuality: | BV3: WS18ExpertCodes: | BW3: OtherConsumerType: | BX3: WS16ExpertCodes: | BY3: ElectricityProducerType: | BZ3: WS17ExpertCodes: | CA3: EMS_ExpertCode: | CB3: EnergyManagementSystemType: | CC3: ConsumerMeterType:
A4: Wohnung | B4: Wohnung | C4: Hotelzimmer | D4: Korridor, Erschliessung | E4: Schulzimmer | F4: Lebensmittel | G4: Restaurant | H4: Frau | I4: schwer | J4: kompakt | K4: Adelboden | L4: Adelboden | M4: Hohe Priorität: Umsetzung in < 2 Jahren | O4: ohne Stern, Pension, Gasthaus | P4: Restaurant | Q4: Discounter | R4: --- | S4: flächig, glatt | T4: neuwertig | U4: W-1 | V4: Aussenwand | W4: N | X4: Pauschal (pro Stück) | Y4: Schrägdach, unbeheizt | Z4: Da-1 | AA4: Steildach | AB4: N | AC4: Fe-1 | AD4: Tür | AE4: N | AF4: unbeheizt | AG4: Bo-1 | AH4: Gegen Aussen | AI4: WL-1 | AJ4: Decke/Wand | AK4: LU-1 | AL4: Externe Berechnung | AM4: Keine Wärmerückgewinnung | AN4: Ohne | AO4: Pauschal (pro Stück) | AP4: WE-1 | AQ4: Elektrizität (HT) | AR4: 1 | AS4: Ölfeuerung | AT4: Heizung (H) | AV4: Gut | AW4: Innerhalb thermischer Gebäudehülle | AX4: SP-1 | AY4: Warmwasserspeicher | BA4: Sehr gut | BB4: HE-1 | BC4: zentral | BD4: Radiatoren | BE4: WE-1 | BF4: nein | BG4: 90/70 | BH4: nein | BI4: WW-1 | BJ4: Zirkulation | BK4: MJ | BL4: Bad/WC-Abluft | BM4: GE-1 | BN4: Sehr gut | BO4: Ja | BP4: KE-1 | BQ4: Bescheiden | BR4: BG-1 | BS4: Top Modern | BT4: BL-1 | BU4: 75-100 % Eff-Leuchten mit Regelung | BV4: WV-1 | BW4: nicht gebäudezugehöriger Verbraucher | BX4: EP-1 | BY4: PV | BZ4: EP-1 | CA4: EM-1 | CB4: Kein EMS | CC4: Elektrizität
A5: Treppenhaus | B5: Treppenhaus | C5: Eingangshalle | D5: Nebenräume | E5: Lehrerzimmer | F5: Fachgeschäft | G5: Verkehrsfläche | H5: Herr | I5: mittel | J5: gestreckt | K5: Altdorf | L5: Aigle | M5: Mittlere Priorität: Umsetzung in 2-5 Jahren | N5: Mehrfamilienhaus | O5: 1 Stern | P5: Selbstbedienungsrestaurant | Q5: Supermarkt | S5: normal gegliedert | T5: gebraucht | U5: W-2 | V5: Hinterlüftete Fassade | W5: NO | X5: Pro m² | Y5: Schrägdach, teilbeheizt | Z5: Da-2 | AA5: Flachdach/Terrasse | AB5: NO | AC5: Fe-2 | AD5: Türe gegen angebauten Raum | AE5: NO | AF5: teilbeheizt | AG5: Bo-2 | AH5: Gegen Unbeheizt (Keller im Erdreich) (ungedämmt und/oder undicht) | AI5: WL-2 | AJ5: Gebäudesockel | AK5: LU-2 | AL5: Fensterlüftung (manuell) | AM5: Kreuzstrom-Wärmetauscher | AN5: AC-Motor | AP5: WE-2 | AQ5: Elektrizität (MT) | AR5: 1.2 | AS5: Ölfeuerung kondensierend | AT5: Warmwasser (WW) | AU5: Radiatoren | AV5: Mittel | AW5: Ausserhalb thermischer Gebäudehülle | AX5: SP-2 | AY5: Heizungsspeicher | AZ5: x | BA5: Gut | BB5: HE-2 | BC5: dezentral | BD5: Flächenheizung | BE5: WE-2 | BF5: ja | BG5: 70/55 | BH5: ja | BI5: WW-2 | BJ5: Heizband | BK5: kWh | BL5: Dampfabzug Abluft | BM5: GE-2 | BN5: Gut | BO5: Nein | BP5: KE-2 | BQ5: Standard | BR5: BG-2 | BS5: Modern | BT5: BL-2 | BU5: 75-100 % Eff-Leuchten | BV5: WV-2 | BW5: gebäudezugehöriger Verbraucher | BX5: EP-2 | BY5: WKK | BZ5: EP-2 | CB5: Einfaches EMS | CC5: Gas
A6: Home-Office | B6: Home-Office | C6: Büro | D6: Büro | E6: Eingangshalle | F6: Möbel, Bau, Garten | G6: Nebenräume | H6: Herr u. Frau | I6: leicht | K6: Basel-Binningen | L6: Altdorf | M6: Geringe Priorität: Umsetzung in 5-10 Jahren | N6: Einfamilienhaus | O6: 2 Sterne | P6: Fastfood-Restaurant | Q6: Gemischtwarenhandel | S6: stark gegliedert | T6: abgenutzt | U6: W-3 | V6: Gegen Unbeheizt (ungedämmt und/oder undicht) | W6: O | Y6: Schrägdach, vollbeheizt | Z6: Da-3 | AA6: Decke/Estrich geg Unbeheizt | AB6: O | AC6: Fe-3 | AD6: Fenster | AE6: O | AF6: vollbeheizt | AG6: Bo-3 | AH6: Gegen Erdreich ≤ 2 m | AI6: WL-3 | AJ6: Balkon | AK6: LU-3 | AL6: Einfache Lüftungsanlage (mit Zu- und Abluft) | AM6: Gegenstrom-Wärmetauscher | AN6: DC/EC-Motor | AP6: WE-3 | AQ6: Elektrizität (NT) | AR6: 1.5 | AS6: Gasfeuerung | AT6: H + WW (ganzjährig) | AU6: Flächenheizung | AV6: Schlecht | AX6: SP-3 | AY6: Kombispeicher | BA6: Mittelmässig | BB6: HE-3 | BD6: Konvektion und Strahlung | BE6: WE-3 | BF6: teilweise | BG6: 55/40 | BH6: unbekannt | BI6: WW-3 | BJ6: keine | BK6: l | BL6: Dampfabzug Umluft | BM6: GE-3 | BN6: Standard | BP6: KE-3 | BQ6: Hoch | BR6: BG-3 | BS6: Standard | BT6: BL-3 | BU6: 25-75 % Eff-Leuchten | BV6: WV-3 | BX6: EP-3 | BZ6: EP-3 | CB6: Zertifiziertes EMS (Minergie)
A7: Keller, Estrich | B7: Keller, Estrich | C7: Verkehrsfläche | D7: Abstellraum, Garage o. ä. | E7: Korridor, Erschliessung | F7: Verkehrsfläche | G7: Büro | H7: Firma | I7: sehr leicht | K7: Bern-Liebefeld | L7: Basel-Binningen | M7: Keine Priorität | N7: Hotel | O7: 3 Sterne | P7: Kantine | Q7: Lebensmittelhandel | T7: Lebensdauer erreicht | U7: W-4 | V7: Gegen Beheizt | W7: SO | Y7: Flachdach | Z7: Da-4 | AA7: Decke/Estrich geg Beheizt | AB7: SO | AC7: Fe-4 | AD7: Fenster gegen angebauten Raum | AE7: SO | AG7: Bo-4 | AH7: Gegen Erdreich > 2 m | AI7: WL-4 | AJ7: Fensteranschlag | AK7: LU-4 | AL7: Lüftungsanlage mit Lufterwärmung (WRG, mit Zu- und Abluft) | AM7: Rotations-Wärmetauscher | AP7: WE-4 | AQ7: Elektrizität (Produktion) | AR7: 2 | AS7: Gasfeuerung kondensierend | AT7: H + WW (nur Heizperiode) | AX7: SP-4 | BA7: Ungenügend | BB7: HE-4 | BE7: WE-4 | BG7: 50/38 | BI7: WW-4 | BK7: m³ | BL7: Elektro-Backofen | BM7: GE-4 | BN7: Schlecht | BP7: KE-4 | BR7: BG-4 | BS7: Veraltet | BT7: BL-4 | BU7: 0-25 % Eff-Leuchten | BV7: WV-4 | BX7: EP-4 | BZ7: EP-4
A8: Abstellraum, Garage o. ä. | B8: Abstellraum, Garage o. ä. | C8: Treppenhaus | E8: Turnhalle | F8: Nebenräume | G8: Garderobe, Duschen, WC | H8: Familie | K8: Buchs-Aarau | L8: Bern-Liebefeld | N8: Büro/Verwaltung | O8: 4 Sterne | P8: Bar | Q8: Detailfachgeschäft | U8: W-5 | V8: Gegen Erdreich ≤ 2 m | W8: S | Y8: Flachdach mit Attikageschoss | Z8: Da-5 | AA8: Geg Unbeh. (Estrich/Dach ged. Ue | AB8: S | AC8: Fe-5 | AD8: Geg Beheizt | AE8: S | AG8: Bo-5 | AH8: Gegen Beheizt | AI8: WL-5 | AJ8: Boden/Kellerwand | AK8: LU-5 | AL8: Lüftungsanlage mit Abluft-Wärmepumpe (mit Zu- und Abluft) | AP8: WE-5 | AQ8: Kohlebrickets | AR8: 3 | AS8: Holzfeuerung (automatisch) | AX8: SP-5 | BB8: HE-5 | BE8: WE-5 | BG8: 45/35 | BI8: WW-5 | BK8: kg | BL8: Elektro-Kochherd | BM8: GE-5 | BP8: KE-5 | BR8: BG-5 | BT8: BL-5 | BV8: WV-5 | BX8: EP-5 | BZ8: EP-5
C9: Nebenfläche | E9: Garderobe, Duschen, WC | F9: Treppenhaus | H9: Hauseigentümer | K9: Chur | L9: Buchs-Aarau | N9: Schule | O9: 5 Sterne und mehr | P9: Café | Q9: Verkauf Möbel, Bau, Garten | U9: W-6 | V9: Gegen Erdreich > 2 m | W9: SW | Z9: Da-6 | AA9: Decke ≤ 2 m im Erdreich | AB9: SW | AC9: Fe-6 | AE9: SW | AG9: Bo-6 | AH9: Gegen Unbeheizt (K. teilw. im Erdreich) (ungedämmt und/oder undicht) | AI9: WL-6 | AJ9: Dach/Aussenwand | AK9: LU-6 | AL9: Einfache Abluftanlage (ohne WRG) | AQ9: Erdgas (inkl. Biogas) | AS9: Holzfeuerung (handbeschickt) | AX9: SP-6 | BB9: HE-6 | BG9: 40/32 | BI9: WW-6 | BK9: Ster | BL9: Gasbackofen | BM9: GE-6 | BP9: KE-6 | BR9: BG-6 | BT9: BL-6 | BV9: WV-6 | BX9: EP-6 | BZ9: EP-6
C10: Abstellraum, Garage o. ä. | E10: Nebenräume | F10: Büro | H10: Eigentümergemeinschaft | K10: Davos | L10: Chur | N10: Verkauf | O10: Jugendheim/Hostel | P10: Eiscafé | U10: W-7 | V10: Gegen Unbeheizt (gedämmt, luftdicht) | W10: W | Z10: Da-7 | AA10: Decke gegen Erdreich > 2 m | AB10: W | AC10: Fe-7 | AE10: W | AG10: Bo-7 | AH10: Gegen Unbeheizt (K. teilw. im Erdreich) (gedämmt, luftdicht) | AI10: WL-7 | AJ10: Rolladen | AK10: LU-7 | AL10: Abluftanlage mit Abwärmenutzung (Abluft-Wärmepumpe) | AQ10: Heizöl | AS10: Pelletfeuerung (automatisch) | AX10: SP-7 | BB10: HE-7 | BG10: 35/28 | BI10: WW-7 | BK10: Sm³ | BL10: Gaskochherd | BM10: GE-7 | BP10: KE-7 | BR10: BG-7 | BT10: BL-7 | BV10: WV-7 | BX10: EP-7 | BZ10: EP-7
E11: Singsaal, Aula | F11: Garderobe, Duschen, WC | H11: Liegenschaftsverwaltung | K11: Disentis | L11: Davos | N11: Restaurant | U11: W-8 | W11: NW | Z11: Da-8 | AB11: NW | AC11: Fe-8 | AE11: NW | AG11: Bo-8 | AH11: Gegen Unbeheizt (Keller im Erdreich) (gedämmt, luftdicht) | AI11: WL-8 | AJ11: Dachrand | AK11: LU-8 | AL11: Einzelraumlüftung (mit WRG) | AQ11: Fernwärme Anteil fossil <= 50 % | AS11: Pelletfeuerung (handbeschickt) | AX11: SP-8 | BB11: HE-8 | BG11: 30/25 | BI11: WW-8 | BK11: kWh HS | BL11: Geschirrspüler (mit Warmwasseranschluss) | BM11: GE-8 | BP11: KE-8 | BR11: BG-8 | BT11: BL-8 | BV11: WV-8 | BX11: EP-8 | BZ11: EP-8
E12: Büro | H12: Gemeindeverwaltung | K12: Engelberg | L12: Disentis | U12: W-9 | Z12: Da-9 | AB12: Horiz | AC12: Fe-9 | AE12: Horiz | AG12: Bo-9 | AI12: WL-9 | AJ12: Innenwand/Aussenwand | AK12: LU-9 | AL12: Fensterlüftung (automatisch) | AQ12: Holzpellets | AS12: Fernwärme | AX12: SP-9 | BB12: HE-9 | BI12: WW-9 | BL12: Geschirrspüler (ohne Warmwasseranschluss) | BM12: GE-9 | BP12: KE-9 | BR12: BG-9 | BT12: BL-9 | BV12: WV-9 | BX12: EP-9 | BZ12: EP-9
E13: Abstellraum, Garage o. ä. | K13: Genève-Cointrin | L13: Engelberg | U13: W-10 | Z13: Da-10 | AC13: Fe-10 | AG13: Bo-10 | AI13: WL-10 | AJ13: Stütze/Träger | AK13: LU-10 | AQ13: Holzschnitzel | AS13: Wärmeversorgung mit BHKW | AX13: SP-10 | BB13: HE-10 | BI13: WW-10 | BL13: Komfortlüftung mit WRG (pro Wohnung) | BM13: GE-10 | BP13: KE-10 | BR13: BG-10 | BT13: BL-10 | BV13: WV-10 | BX13: EP-10 | BZ13: EP-10
K14: Glarus | L14: Genève-Cointrin | U14: Wx-1 | Z14: De-1 | AC14: T-1 | AG14: Bx-1 | AI14: WR-1 | AJ14: Benutzerdefiniert - Punktförmig | AQ14: Stückholz | AS14: Mini-BHKW | BL14: Kühlschrank < 160 l, mit Tiefkühlfach
K15: Grand-St-Bernard | L15: Glarus | U15: Wx-2 | Z15: De-2 | AC15: T-2 | AG15: Bx-2 | AI15: WR-2 | AJ15: Benutzerdefiniert - Linear | AQ15: Thermische Sonnenenergie | AS15: Elektrospeicher- Zentralheizung | BL15: Kühlschrank < 160 l, ohne Tiefkühlfach
K16: Güttingen | L16: Grand-St-Bernard | U16: Wx-3 | Z16: De-3 | AC16: T-3 | AG16: Bx-3 | AI16: WR-3 | AQ16: Elektrizität (Wärmepumpe) | AS16: Elektro direkt | BL16: Kühlschrank > 160 l, mit Tiefkühlfach
K17: La Chaux-de-Fonds | L17: Güttingen | U17: Wx-4 | Z17: De-4 | AC17: T-4 | AG17: Bx-4 | AI17: WR-4 | AQ17: Fernwärme Anteil fossil <= 25 % | AS17: Elektro-Wassererwärmer | BL17: Kühlschrank > 160 l, ohne Tiefkühlfach
K18: Locarno-Monti | L18: Interlaken | U18: Wx-5 | Z18: De-5 | AC18: T-5 | AG18: Bx-5 | AI18: WR-5 | AQ18: Fernwärme Anteil fossil <= 75 % | AS18: Wärmepumpe, Aussenluft | BL18: Lift
K19: Lugano | L19: La Chaux-de-Fonds | U19: Wx-6 | Z19: De-6 | AC19: T-6 | AG19: Bx-6 | AI19: WR-6 | AQ19: Fernwärme Anteil fossil > 75 % | AS19: Wärmepumpe, Erdwärmesonde | BL19: Raumlufttrockner
K20: Luzern | L20: La Frétaz | U20: Wx-7 | Z20: De-7 | AC20: T-7 | AG20: Bx-7 | AI20: WR-7 | AS20: Wärmepumpe, Abwasser | BL20: Separates Gefriergerät (gross)
K21: Magadino | L21: Locarno-Monti | U21: Wx-8 | Z21: De-8 | AC21: T-8 | AG21: Bx-8 | AI21: WR-8 | AS21: Wärmepumpe, Grundwasser, direkt | BL21: Separates Gefriergerät (klein)
K22: Montana | L22: Lugano | U22: Wx-9 | Z22: De-9 | AC22: T-9 | AG22: Bx-9 | AI22: WR-9 | AS22: Wärmepumpe, Grundwasser, indirekt | BL22: Wäschetrocknung
K23: Neuchâtel | L23: Luzern | U23: Wx-10 | Z23: De-10 | AC23: T-10 | AG23: Bx-10 | AI23: WR-10 | AS23: Wärmepumpe Erdregister | BL23: Waschmaschine (mit Warmwasseranschluss)
K24: Payerne | L24: Magadino | AS24: Lüftungsgerät mit Abluft / Zuluft - WP plus WRG | BL24: Waschmaschine (ohne Warmwasseranschluss)
K25: Robbia | L25: Montana | AS25: Lüftungsgerät mit Abluft / Zuluft - WP ohne WRG
K26: Samedan | L26: Neuchâtel | AS26: Lüftungsgerät mit Abluft-Wärmepumpe (keine Zuluft)
K27: San Bernardino | L27: Payerne | AS27: Kompakt-WP mit Zu- & Abluft / WW plus WRG
K28: Schaffhausen | L28: Piotta | AS28: Kompakt-WP mit Zu- & Abluft / WW ohne WRG
K29: Scuol | L29: Pully | AS29: Solarenergie thermisch
K30: Sion | L30: Robbia | AS30: Wärmepumpenboiler Trinkwarmwasser
K31: St. Gallen | L31: Rünenberg | AS31: Holzofen als Zusatzheizung
K32: Vaduz | L32: Samedan
K33: Wynau | L33: San Bernardino
K34: Zermatt | L34: Schaffhausen
K35: Zürich-MeteoSchweiz | L35: Scuol
L36: Sion
L37: St. Gallen
L38: Ulrichen
L39: Vaduz
L40: Wynau
L41: Zermatt
...

Sheet WallOpeningParents
A1: =IF(AND('Dächer und Decken'!A11<>"",LEN('Dächer und Decken'!A11)<10),'Dächer und Decken'!A11,"") | B1: {=IF(ROWS(B$1:B1)>SUMPRODUCT(--(A:A<>"")),"",INDEX(A:A,SMALL(IF(A$1:A$200<>"",ROW(A$1:A$200)),ROWS(B$1:B1))))}
A2: =IF(AND('Dächer und Decken'!A12<>"",LEN('Dächer und Decken'!A12)<10),'Dächer und Decken'!A12,"") | B2: {=IF(ROWS(B$1:B2)>SUMPRODUCT(--(A:A<>"")),"",INDEX(A:A,SMALL(IF(A$1:A$200<>"",ROW(A$1:A$200)),ROWS(B$1:B2))))}
A3: =IF(AND('Dächer und Decken'!A13<>"",LEN('Dächer und Decken'!A13)<10),'Dächer und Decken'!A13,"") | B3: {=IF(ROWS(B$1:B3)>SUMPRODUCT(--(A:A<>"")),"",INDEX(A:A,SMALL(IF(A$1:A$200<>"",ROW(A$1:A$200)),ROWS(B$1:B3))))}
A4: =IF(AND('Dächer und Decken'!A14<>"",LEN('Dächer und Decken'!A14)<10),'Dächer und Decken'!A14,"") | B4: {=IF(ROWS(B$1:B4)>SUMPRODUCT(--(A:A<>"")),"",INDEX(A:A,SMALL(IF(A$1:A$200<>"",ROW(A$1:A$200)),ROWS(B$1:B4))))}
A5: =IF(AND('Dächer und Decken'!A15<>"",LEN('Dächer und Decken'!A15)<10),'Dächer und Decken'!A15,"") | B5: {=IF(ROWS(B$1:B5)>SUMPRODUCT(--(A:A<>"")),"",INDEX(A:A,SMALL(IF(A$1:A$200<>"",ROW(A$1:A$200)),ROWS(B$1:B5))))}
A6: =IF(AND('Dächer und Decken'!A16<>"",LEN('Dächer und Decken'!A16)<10),'Dächer und Decken'!A16,"") | B6: {=IF(ROWS(B$1:B6)>SUMPRODUCT(--(A:A<>"")),"",INDEX(A:A,SMALL(IF(A$1:A$200<>"",ROW(A$1:A$200)),ROWS(B$1:B6))))}
A7: =IF(AND('Dächer und Decken'!A17<>"",LEN('Dächer und Decken'!A17)<10),'Dächer und Decken'!A17,"") | B7: {=IF(ROWS(B$1:B7)>SUMPRODUCT(--(A:A<>"")),"",INDEX(A:A,SMALL(IF(A$1:A$200<>"",ROW(A$1:A$200)),ROWS(B$1:B7))))}
A8: =IF(AND('Dächer und Decken'!A18<>"",LEN('Dächer und Decken'!A18)<10),'Dächer und Decken'!A18,"") | B8: {=IF(ROWS(B$1:B8)>SUMPRODUCT(--(A:A<>"")),"",INDEX(A:A,SMALL(IF(A$1:A$200<>"",ROW(A$1:A$200)),ROWS(B$1:B8))))}
A9: =IF(AND('Dächer und Decken'!A19<>"",LEN('Dächer und Decken'!A19)<10),'Dächer und Decken'!A19,"") | B9: {=IF(ROWS(B$1:B9)>SUMPRODUCT(--(A:A<>"")),"",INDEX(A:A,SMALL(IF(A$1:A$200<>"",ROW(A$1:A$200)),ROWS(B$1:B9))))}
A10: =IF(AND('Dächer und Decken'!A20<>"",LEN('Dächer und Decken'!A20)<10),'Dächer und Decken'!A20,"") | B10: {=IF(ROWS(B$1:B10)>SUMPRODUCT(--(A:A<>"")),"",INDEX(A:A,SMALL(IF(A$1:A$200<>"",ROW(A$1:A$200)),ROWS(B$1:B10))))}
A11: =IF(AND('Dächer und Decken'!A21<>"",LEN('Dächer und Decken'!A21)<10),'Dächer und Decken'!A21,"") | B11: {=IF(ROWS(B$1:B11)>SUMPRODUCT(--(A:A<>"")),"",INDEX(A:A,SMALL(IF(A$1:A$200<>"",ROW(A$1:A$200)),ROWS(B$1:B11))))}
A12: =IF(AND('Dächer und Decken'!A22<>"",LEN('Dächer und Decken'!A22)<10),'Dächer und Decken'!A22,"") | B12: {=IF(ROWS(B$1:B12)>SUMPRODUCT(--(A:A<>"")),"",INDEX(A:A,SMALL(IF(A$1:A$200<>"",ROW(A$1:A$200)),ROWS(B$1:B12))))}
... A100: =IF(AND('Dächer und Decken'!A110<>"",LEN('Dächer und Decken'!A110)<10),'Dächer und Decken'!A110,"") | B100: {=IF(ROWS(B$1:B100)>SUMPRODUCT(--(A:A<>"")),"",INDEX(A:A,SMALL(IF(A$1:A$200<>"",ROW(A$1:A$200)),ROWS(B$1:B100))))}
A101: =IF(AND(Wände!A11<>"",LEN(Wände!A11)<10),Wände!A11,"") | B101: {=IF(ROWS(B$1:B101)>SUMPRODUCT(--(A:A<>"")),"",INDEX(A:A,SMALL(IF(A$1:A$200<>"",ROW(A$1:A$200)),ROWS(B$1:B101))))}
A102: =IF(AND(Wände!A12<>"",LEN(Wände!A12)<10),Wände!A12,"") | B102: {=IF(ROWS(B$1:B102)>SUMPRODUCT(--(A:A<>"")),"",INDEX(A:A,SMALL(IF(A$1:A$200<>"",ROW(A$1:A$200)),ROWS(B$1:B102))))}
A103: =IF(AND(Wände!A13<>"",LEN(Wände!A13)<10),Wände!A13,"") | B103: {=IF(ROWS(B$1:B103)>SUMPRODUCT(--(A:A<>"")),"",INDEX(A:A,SMALL(IF(A$1:A$200<>"",ROW(A$1:A$200)),ROWS(B$1:B103))))}
A104: =IF(AND(Wände!A14<>"",LEN(Wände!A14)<10),Wände!A14,"") | B104: {=IF(ROWS(B$1:B104)>SUMPRODUCT(--(A:A<>"")),"",INDEX(A:A,SMALL(IF(A$1:A$200<>"",ROW(A$1:A$200)),ROWS(B$1:B104))))}
A105: =IF(AND(Wände!A15<>"",LEN(Wände!A15)<10),Wände!A15,"") | B105: {=IF(ROWS(B$1:B105)>SUMPRODUCT(--(A:A<>"")),"",INDEX(A:A,SMALL(IF(A$1:A$200<>"",ROW(A$1:A$200)),ROWS(B$1:B105))))}
A106: =IF(AND(Wände!A16<>"",LEN(Wände!A16)<10),Wände!A16,"") | B106: {=IF(ROWS(B$1:B106)>SUMPRODUCT(--(A:A<>"")),"",INDEX(A:A,SMALL(IF(A$1:A$200<>"",ROW(A$1:A$200)),ROWS(B$1:B106))))}
A107: =IF(AND(Wände!A17<>"",LEN(Wände!A17)<10),Wände!A17,"") | B107: {=IF(ROWS(B$1:B107)>SUMPRODUCT(--(A:A<>"")),"",INDEX(A:A,SMALL(IF(A$1:A$200<>"",ROW(A$1:A$200)),ROWS(B$1:B107))))}
A108: =IF(AND(Wände!A18<>"",LEN(Wände!A18)<10),Wände!A18,"") | B108: {=IF(ROWS(B$1:B108)>SUMPRODUCT(--(A:A<>"")),"",INDEX(A:A,SMALL(IF(A$1:A$200<>"",ROW(A$1:A$200)),ROWS(B$1:B108))))}
A109: =IF(AND(Wände!A19<>"",LEN(Wände!A19)<10),Wände!A19,"") | B109: {=IF(ROWS(B$1:B109)>SUMPRODUCT(--(A:A<>"")),"",INDEX(A:A,SMALL(IF(A$1:A$200<>"",ROW(A$1:A$200)),ROWS(B$1:B109))))}
A110: =IF(AND(Wände!A20<>"",LEN(Wände!A20)<10),Wände!A20,"") | B110: {=IF(ROWS(B$1:B110)>SUMPRODUCT(--(A:A<>"")),"",INDEX(A:A,SMALL(IF(A$1:A$200<>"",ROW(A$1:A$200)),ROWS(B$1:B110))))}
A111: =IF(AND(Wände!A21<>"",LEN(Wände!A21)<10),Wände!A21,"") | B111: {=IF(ROWS(B$1:B111)>SUMPRODUCT(--(A:A<>"")),"",INDEX(A:A,SMALL(IF(A$1:A$200<>"",ROW(A$1:A$200)),ROWS(B$1:B111))))}
A112: =IF(AND(Wände!A22<>"",LEN(Wände!A22)<10),Wände!A22,"") | B112: {=IF(ROWS(B$1:B112)>SUMPRODUCT(--(A:A<>"")),"",INDEX(A:A,SMALL(IF(A$1:A$200<>"",ROW(A$1:A$200)),ROWS(B$1:B112))))}
... A200: =IF(AND(Wände!A110<>"",LEN(Wände!A110)<10),Wände!A110,"") | B200: {=IF(ROWS(B$1:B200)>SUMPRODUCT(--(A:A<>"")),"",INDEX(A:A,SMALL(IF(A$1:A$200<>"",ROW(A$1:A$200)),ROWS(B$1:B200))))}
